
># 异常处理语法

try和catch结构的工作就是用来捕获和处理异常的，语法如下所示：
```
￼
try￼
{￼
// 可能出现错误的程序代码内容￼
}￼

catch(发生异常的错误类型p1)￼
{￼
// 处理异常￼
}￼

catch(发生异常的错误类型p2)￼
{￼
// 处理异常￼
}
```


&emsp;	try指令：
<br/>

&emsp;	在try区块中，通常后面会跟着一个或多个catch区块，在每一个catch区块中都会指定它所能处理错误的数据类型与用来识别的参数（在此为p1和p2）。每一个catch区块中都包含一段处理异常的程序代码。当在try区块内的程序代码发生错误时，系统会自异常发生点抛出一个异常；当所抛出的异常符合其中某一个catch异常区块的参数类型时，系统就会执行那个catch区块内的程序代码。

&emsp;	如果所抛出的异常并没有符合任何catch异常区块的参数类型，就会跳过所有的catch区块，直接将控制权移至最后一个catch区块的下一行程序代码继续执行。

&emsp;	另外，当发生异常时，我们使用“throw”关键字将异常抛出，而throw关键字后面可以接受任何类型的操作数，包括基本类型的变量、字符串或类所创建的对象，如下所示：

```
try￼
{￼
if(条件判断式)￼
  throw变量或常数值； // 抛出异常情况￼
}￼
catch(数据类型 变量名称)￼
{￼
// 异常情况处理区块￼
}￼
catch(数据类型 变量名称)￼
{￼
// 异常情况处理区块￼
}￼
……
```

案例：

```
include<iostream>￼
#include<cstdlib>￼
using namespace std;￼
int main()￼
{￼
    cout<<"==简单的例外范例==\n";￼
    //使用try...catch来捕获异常￼
    try￼
    {￼
        int n1;￼
        cout<<"请输入除数：";￼
        cin>>n1; //输入除数值￼
        if (n1==0)￼
            //判断输入的值是否为“0”。输入的值为“0”时就使用关键字“throw”来抛出一个异常，并指定此异常的类型为整数类型。接着系统会将控制权直接转移至第19行的程序语句。
            throw 1;  //若除数为0时，则抛出一个异常￼
        //没有抛出异常时，此行的程序语句才会执行。
        cout<<"没有捕获到例外"<<endl; //当捕获到异常时，此行并不会执行￼
        
    }￼
    catch(int i)  //找到符合的catch区块类型￼
    {￼
        cout<<"捕获到除数为0的例外"<<endl;￼
    }￼
    cout<<"结束程序的执行"<<endl; //提示已至程序代码的尾端￼
    system("pause");￼
    return 0;￼
}
```

![z3](https://raw.githubusercontent.com/harleyGit/StudyNotes/master/Pictures/z3.png)

![z4](https://raw.githubusercontent.com/harleyGit/StudyNotes/master/Pictures/z4.png)
![z5](https://raw.githubusercontent.com/harleyGit/StudyNotes/master/Pictures/z5.png)






<br/>

***
<br/>



># catch区块重载
&emsp;	如果在try区块中所抛出的类型异常不止一种，也就是后面跟着多个catch区块，则称为catch区块的重载。补充说明一点，catch区块所处理的异常情况必须定义在一对`’{}’`括号内，一个try区块可以对应多个`catch`区块，但先决条件是try区块与`catch`区块之间不能含有任何运算符或表达式。

```
#include<iostream>￼
#include<cstdlib>￼
using namespace std;￼
int main()￼
{￼
    int num;  // 声明一个整数变量num￼
    try  //最内层的try...catch区块￼
    {￼
        cout<<"输入一个值：";￼
        cin>>num;￼
        // 判断变量值num是否大于0且小于10￼
        if ((num > 0) && (num < 10))￼
        {￼
            throw 1; //当变量num的值大于0且小于10时，抛出一个类型为整数的异常￼
        }￼
        // 判断变量值num是否大于10且小于20￼
        if ((num > 10) && (num < 20))￼
        {￼
            throw 0.99;
            //当变量num的值大于10且小于20时，抛出一个类型为实数的异常￼
        }￼
        catch(int ex1)  // 捕获类型为整数的异常￼
        {￼
            cout<<"执行整数的例外"<<endl;￼
        }￼
        catch(double ex2)  // 捕获类型为实数的异常￼
        {￼
            cout<<"执行实数的例外"<<endl;￼
        }￼
        cout<<"程序将要结束运行"<<endl;￼
        system("pause");￼
        return 0;￼
    }




```





<br/>

***
<br/>



># 嵌套try…catch区块

&emsp;	通常当异常发生时，在try区块内所抛出的异常是由最靠近的catch异常处理程序区块来捕获的，当异常被抛出之后会发生一些相关的操作。首先它会创建一份我们所抛出异常的对象副本，并给它设置初值。接着此对象会给异常处理区块内的参数设置初值，当异常处理区块执行完毕之后，系统就会将此对象副本清除。
到目前为止，大家应该清楚当异常被抛出时程序的控制权会从当前的try区块离开，然后将控制权交给在try区块之后某一个符合类型的catch异常处理程序区块（假如存在的话）。
所谓嵌套try…catch区块的定义方式是，在try区块内再定义一组try区块（至少一个try区块对应一个catch区块)，如下所示：
```
try￼
{￼

try￼
{￼

// 可能发生错误的程序代码￼
}￼

catch(数据类型 变量名称)￼
{￼
// 异常情况处理区块￼
}￼
}￼
catch(数据类型 变量名称)￼
{￼
// 异常情况处理区块￼
}
```

&emsp;	在嵌套try区块中，外层的catch区块负责外层try区块的异常捕获，内层的catch区块负责内层try区块的异常捕获，当内层的catch区块未能捕获异常情况时会交由外层catch区块捕获，内外层catch区块都未能捕获异常时，该异常情况最后将交由标准函数库中的terminate()函数处理。



<br/>

***
<br/>



># 重新抛出异常

&emsp;	当需要将某些资源释放给其他人来处理异常时，或者是某个catch区块无法处理所捕获到的异常时，必须要重新抛出异常。要重新抛出异常，只要下达一个不带参数的“throw”语句即可：
```￼
throw;
例如：
￼
catch(...)￼
{￼

cout << "an exception was thrown" << endl;￼

 // 在此将所分配的资源释放并重新抛出异常
￼
throw;￼

}
```
&emsp;	注意，当我们在try区块内任何一个catch区块中下达throw语句时，在throw语句之后所有catch区块将不会执行，而是交给更外一层的catch区块来进行处理。

&emsp;	下面的范例程序用于示范当在函数throwex()内的第一个try区块中抛出一个标准链接库类exception的对象时，这个异常将会被第二个catch区块所捕获到，并显示“当前异常控制权是在函数throwex的第二层try区块中”的文字以及重新抛出一个异常。一旦下达throw语句之后，就会将控制权转移至最外层的try区块（也就是第一个try区块）中，并由最外层也就是第一层的catch所捕获到，然后显示“捕获所有的例外”文字。
￼
```
#include<iostream>￼
#include<cstdlib>￼
using namespace std;￼
void throwex()￼
{￼
    try  // 外层的try区块￼
    {￼
        try {  // 内层的try区块￼
            throw exception(); //抛出一个异常￼
        }￼
        catch(exception e)  //捕获异常￼
        {￼
            cout<<"当前例外控制权是在函数throwex的第二层try区块中"<<endl;￼
            throw; //重新抛出一个异常￼
        }￼
        catch(...) //捕获所有的异常￼
        {￼
            cout<<"第一层try区块，捕获所有的例外"<<endl;￼
        }￼
    }￼
    int main()￼
    {￼
        try {￼
            throwex();  //调用函数throwex￼
            cout<<"在函数main内的try区块"<<endl;￼
        }￼
        catch(exception e)  //捕获异常￼
        {￼
            cout<<"当前例外控制权是在主函数main中"<<endl;￼
        }￼
        cout<<"程序运行完毕"<<endl;￼
        system("pause");￼
        return 0;￼
    }


```









<br/>

***
<br/>

&emsp;	在C++语言中模板有两种，分别为“函数模板”（Function Template）与“类模板”（Class Template）。

&emsp;	函数模板就是把具有相同程序代码的函数集中写成一个函数，并且把各个函数不同数据类型的部分改以模板形式参数来替代，即可通过传递不同数据类型的参数来创建实例函数。函数模板的声明格式与说明如下：
```￼
 template <class模板形式参数1, class模板形式参数2, ……>￼
￼
￼
 返回数据类型 函数名称(参数1, 参数2, ……)￼
 {￼
   // 函数内的语句区块￼
 }

template<class T>￼
￼
￼
 T func(T n)￼
 {￼
     T result;￼
     result = n ＊ n + 3 ＊ n + 5;￼
     return result;￼
 }
```

实际调用：
```
#include <iostream>￼
#include <cstdlib>￼
using namespace std;￼
template<class T>      //定义与声明func模板函数￼
T func(T n)￼
{￼
    T result;      //声明result为T类型变量￼
    result = n ＊ n + 3 ＊ n + 5;
    //执行n＊n+3＊n+5运算，并将结果赋值给result￼
    return result;           //返回result￼
}￼
int main()￼
{￼
    cout<<"func(10) = ";￼
    cout<<func(10)<<endl;    //输出func(10)的运算结果￼
    cout<<"func(12.5f) = ";￼
    cout<<func(12.5f)<<endl;     //输出func(12.5f)的运算结果￼
    system("pause");￼
    return 0;￼
}


```
【运行结果】如图所示：


 

























